Workbook

Sheet Shear flow
A1: Panel | B1: Boom | C1: Boom area | D1: Boom y pos from neutral | E1: A_br* yr | F1: qb | G1: x1y2-x2-y2 | I1: Shear force N/mm | J1: Panel thickness (mm) | K1: Shear stress (N/mm^2)
A2: 10-1 | B2: cut | F2: 0 | G2: =('Fuselage Stresses'!C22*'Fuselage Stresses'!D13)-('Fuselage Stresses'!C13*'Fuselage Stresses'!D22) -> 0 | H2: =F2*G2 -> 0 | I2: =F2 -> 0 | J2: ='Fuselage Stresses'!$C$25 -> 0.2 | K2: =I2/J2 -> 0 | N2: Shear Force | O2: ='Fuselage Stresses'!$Q$26 -> 5690 | P2: N
A3: 1-2 | B3: 1 | C3: ='Fuselage Stresses'!P13 -> 179.94461 | D3: ='Fuselage Stresses'!$D$13-'Fuselage Stresses'!$I$28 -> -600.00782 | E3: =C3*D3 -> -107968.18 | F3: =$B$17*E3 -> 0.46119969 | G3: =('Fuselage Stresses'!C13*'Fuselage Stresses'!D14)-('Fuselage Stresses'!C14*'Fuselage Stresses'!D13) -> -340000 | H3: =F3*G3 -> -156807.9 | I3: =F3 -> 0.46119969 | J3: ='Fuselage Stresses'!$C$25 -> 0.2 | K3: =I3/J3 -> 2.3059985
A4: 2-3 | B4: 2 | C4: ='Fuselage Stresses'!P14 -> 2524.6712 | D4: ='Fuselage Stresses'!$D$14-'Fuselage Stresses'!$I$28 -> -100.00782 | E4: =C4*D4 -> -252486.87 | F4: =F3+($B$17*E4) -> 1.5397292 | G4: =('Fuselage Stresses'!C14*'Fuselage Stresses'!D15)-('Fuselage Stresses'!C15*'Fuselage Stresses'!D14) -> -560000 | H4: =F4*G4 -> -862248.37 | I4: =F4 -> 1.5397292 | J4: ='Fuselage Stresses'!$C$25 -> 0.2 | K4: =I4/J4 -> 7.6986462
A5: 3-4 | B5: 3 | C5: ='Fuselage Stresses'!P15 -> 190.77776 | D5: ='Fuselage Stresses'!$D$15-'Fuselage Stresses'!$I$28 -> 599.99218 | E5: =C5*D5 -> 114465.16 | F5: =F4+($B$17*E5) -> 1.0507768 | G5: =('Fuselage Stresses'!C15*'Fuselage Stresses'!D16)-('Fuselage Stresses'!C16*'Fuselage Stresses'!D15) -> -845000 | H5: =F5*G5 -> -887906.42 | I5: =F5 -> 1.0507768 | J5: ='Fuselage Stresses'!$C$25 -> 0.2 | K5: =I5/J5 -> 5.2538842
A6: 4-5 | B6: 4 | C6: ='Fuselage Stresses'!P16 -> 165.32426 | D6: ='Fuselage Stresses'!$D$16-'Fuselage Stresses'!$I$28 -> 1249.9922 | E6: =C6*D6 -> 206654.03 | F6: =F5+($B$17*E6) -> 0.16802808 | G6: =('Fuselage Stresses'!C16*'Fuselage Stresses'!D17)-('Fuselage Stresses'!C17*'Fuselage Stresses'!D16) -> -1155000 | H6: =F6*G6 -> -194072.43 | I6: =F6 -> 0.16802808 | J6: ='Fuselage Stresses'!$C$25 -> 0.2 | K6: =I6/J6 -> 0.84014039
A7: 10-9 | B7: 10 | C7: ='Fuselage Stresses'!$P$22 -> 242.38104 | D7: ='Fuselage Stresses'!D22-'Fuselage Stresses'!I28 -> -700.00782 | E7: =C7*D7 -> -169668.62 | F7: 0 | G7: =('Fuselage Stresses'!C22*'Fuselage Stresses'!D21)-('Fuselage Stresses'!C21*'Fuselage Stresses'!D22) -> 0 | H7: =F7*G7 -> 0 | I7: =F7 -> 0 | J7: ='Fuselage Stresses'!$C$25 -> 0.2 | K7: =I7/J7 -> 0
A8: 9-8 | B8: 9 | C8: ='Fuselage Stresses'!$P$21 -> 179.94461 | D8: ='Fuselage Stresses'!D21-'Fuselage Stresses'!I28 -> -600.00782 | E8: =C8*D8 -> -107968.18 | F8: =B17*E8 -> 0.46119969 | G8: =('Fuselage Stresses'!C21*'Fuselage Stresses'!D20)-('Fuselage Stresses'!C20*'Fuselage Stresses'!D21) -> 340000 | H8: =F8*G8 -> 156807.9 | I8: =F8 -> 0.46119969 | J8: ='Fuselage Stresses'!$C$25 -> 0.2 | K8: =I8/J8 -> 2.3059985 | N8: tau = q/t
A9: 8-7 | B9: 8 | C9: ='Fuselage Stresses'!$P$20 -> 2524.6712 | D9: ='Fuselage Stresses'!D20-'Fuselage Stresses'!I28 -> -100.00782 | E9: =C9*D9 -> -252486.87 | F9: =F8+(E9*$B$17) -> 1.5397292 | G9: =('Fuselage Stresses'!C20*'Fuselage Stresses'!D19)-('Fuselage Stresses'!C19*'Fuselage Stresses'!D20) -> 560000 | H9: =F9*G9 -> 862248.37 | I9: =F9 -> 1.5397292 | J9: ='Fuselage Stresses'!$C$25 -> 0.2 | K9: =I9/J9 -> 7.6986462
A10: 7-6 | B10: 7 | C10: ='Fuselage Stresses'!$P$19 -> 190.77776 | D10: ='Fuselage Stresses'!D19-'Fuselage Stresses'!I28 -> 599.99218 | E10: =C10*D10 -> 114465.16 | F10: =F9+(E10*$B$17) -> 1.0507768 | G10: =('Fuselage Stresses'!C19*'Fuselage Stresses'!D18)-('Fuselage Stresses'!C18*'Fuselage Stresses'!D19) -> 845000 | H10: =F10*G10 -> 887906.42 | I10: =F10 -> 1.0507768 | J10: ='Fuselage Stresses'!$C$25 -> 0.2 | K10: =I10/J10 -> 5.2538842
A11: 6-5 | B11: 6 | C11: ='Fuselage Stresses'!$P$18 -> 165.32426 | D11: ='Fuselage Stresses'!D18-'Fuselage Stresses'!I28 -> 1249.9922 | E11: =C11*D11 -> 206654.03 | F11: =F10+(E11*$B$17) -> 0.16802808 | G11: =('Fuselage Stresses'!C18*'Fuselage Stresses'!D17)-('Fuselage Stresses'!C17*'Fuselage Stresses'!D18) -> 1155000 | H11: =F11*G11 -> 194072.43 | I11: =F11 -> 0.16802808 | J11: ='Fuselage Stresses'!$C$25 -> 0.2 | K11: =I11/J11 -> 0.84014039
A12: Total | H12: =SUM(H2:H11) -> 0 | I12: ≈0
A14: Area | B14: =2.96*10^6 -> 2960000 | C14: mm^2
B15: =B14/10^6 -> 2.96 | C15: m^2
A17: Shear/Ixx | B17: =-O2/'Fuselage Stresses'!N23 -> -4.2716262e-06 | U17: Becasue shape is symtrical and shear force acts through middle of fuselage the, here is no torque meaning no constant shear flow is needed

Sheet Fuselage Stresses
A1: Section | B1: Stiffners | C1: x (mm) | D1: y (mm) | E1: L (mm) | F1: t (mm) | G1: A (mm^2) | H1: x*A | I1: y*A | J1: X true | K1: Y True | L1: Stress Rat | M1: DIxx Real | N1: DIxx Ideal | P1: Boom Area | Q1: Stress
A2: 1-2 | C2: -795 | D2: 350 | E2: 630 | F2: =$C$25 -> 0.2 | G2: =F2*E2 -> 126 | H2: =C2*G2 -> -100170 | I2: =D2*G2 -> 44100 | J2: =C2-$I$27 -> -795 | K2: =D2-$I$28 -> -350.00782 | L2: =ABS(K13/K14) -> 5.9996089
A3: 2-3 | C3: -800 | D3: 950 | E3: 700 | F3: =$C$25 -> 0.2 | G3: =F3*E3 -> 140 | H3: =C3*G3 -> -112000 | I3: =D3*G3 -> 133000 | J3: =C3-$I$27 -> -800 | K3: =D3-$I$28 -> 249.99218 | L3: =ABS(K14/K15) -> 0.16668188
A4: 3-4 | C4: -690 | D4: 1625 | E4: 720 | F4: =$C$25 -> 0.2 | G4: =F4*E4 -> 144 | H4: =C4*G4 -> -99360 | I4: =D4*G4 -> 234000 | J4: =C4-$I$27 -> -690 | K4: =D4-$I$28 -> 924.99218 | L4: =ABS(K15/K16) -> 0.47999675
A5: 4-5 | C5: -275 | D5: 2065 | E5: 536.58 | F5: =$C$25 -> 0.2 | G5: =F5*E5 -> 107.316 | H5: =C5*G5 -> -29511.9 | I5: =D5*G5 -> 221607.54 | J5: =C5-$I$27 -> -275 | K5: =D5-$I$28 -> 1364.9922 | L5: =ABS(K16/K17) -> 0.89285654
A6: 5-6 | C6: 275 | D6: 2065 | E6: 536.58 | F6: =$C$25 -> 0.2 | G6: =F6*E6 -> 107.316 | H6: =C6*G6 -> 29511.9 | I6: =D6*G6 -> 221607.54 | J6: =C6-$I$27 -> 275 | K6: =D6-$I$28 -> 1364.9922 | L6: =ABS(K17/K18) -> 1.1200008
A7: 6-7 | C7: 690 | D7: 1625 | E7: 720 | F7: =$C$25 -> 0.2 | G7: =F7*E7 -> 144 | H7: =C7*G7 -> 99360 | I7: =D7*G7 -> 234000 | J7: =C7-$I$27 -> 690 | K7: =D7-$I$28 -> 924.99218 | L7: =ABS(K18/K19) -> 2.0833475
A8: 7-8 | C8: 800 | D8: 950 | E8: 700 | F8: =$C$25 -> 0.2 | G8: =F8*E8 -> 140 | H8: =C8*G8 -> 112000 | I8: =D8*G8 -> 133000 | J8: =C8-$I$27 -> 800 | K8: =D8-$I$28 -> 249.99218 | L8: =ABS(K19/K20) -> 5.9994525
A9: 8-9 | C9: 795 | D9: 230 | E9: 630 | F9: =$C$25 -> 0.2 | G9: =F9*E9 -> 126 | H9: =C9*G9 -> 100170 | I9: =D9*G9 -> 28980 | J9: =C9-$I$27 -> 795 | K9: =D9-$I$28 -> -470.00782 | L9: =ABS(K20/K21) -> 0.16667753
A10: 9-10 | C10: 400 | D10: 0 | E10: 800 | F10: =$C$25 -> 0.2 | G10: =F10*E10 -> 160 | H10: =C10*G10 -> 64000 | I10: =D10*G10 -> 0 | J10: =C10-$I$27 -> 400 | K10: =D10-$I$28 -> -700.00782 | L10: =ABS(K21/K22) -> 0.85714445
A11: 10-1 | C11: -400 | D11: 0 | E11: 800 | F11: =$C$25 -> 0.2 | G11: =F11*E11 -> 160 | H11: =C11*G11 -> -64000 | I11: =D11*G11 -> 0 | J11: =C11-$I$27 -> -400 | K11: =D11-$I$28 -> -700.00782 | L11: =ABS(K22/K13) -> 1.1666645
A12: 2-8 | C12: 0 | D12: 600 | E12: 1600 | F12: =3 -> 3 | G12: =F12*E12 -> 4800 | H12: =C12*G12 -> 0 | I12: =D12*G12 -> 2880000 | J12: =C12-$I$27 -> 0 | K12: =D12-$I$28 -> -100.00782 | L12: =ABS(K14/K20) -> 1 | R12: Shear stress MPa | S12: Sigma 1 | T12: Sigma 2 | U12: Sigma_vm | V12: VM * FOS (1.5)
B13: 1 | C13: -700 | D13: 100 | G13: =$C$27 -> 50 | H13: =C13*G13 -> -35000 | I13: =D13*G13 -> 5000 | J13: =C13-$I$27 -> -700 | K13: =D13-$I$28 -> -600.00782 | N13: =(K13^2)*P13 -> 64781750 | P13: =G13+((E11*F11/6*(2+(K22/K13)))+(E2*F2/6*(2+(K14/K13)))) -> 179.94461 | Q13: =$N$26*K13/$N$23*1000 -> -3.4832601 | R13: ='Shear flow'!K3 -> 2.3059985 | S13: =(Q13/2)+SQRT(((-Q13/2)^2)+(((R13^2)))) -> 1.1481631 | T13: =(0+Q13/2)-SQRT(((0-Q13/2)^2)+((R13^2))) -> -4.6314231 | U13: =SQRT((S13^2 +T13^2 )-(S13*T13)) -> 5.2996214 | V13: =U13*1.5 -> 7.9494322
B14: 2 | C14: -800 | D14: 600 | G14: =$C$27 -> 50 | H14: =C14*G14 -> -40000 | I14: =D14*G14 -> 30000 | J14: =C14-$I$27 -> -800 | K14: =D14-$I$28 -> -100.00782 | N14: =(K14^2)*P14 -> 25250662 | P14: =G14+((E2*F2/6*(2+(K13/K14)))+(E3*F3/6*(2+K15/K14))+(E12*F12/6*(2+L12))) -> 2524.6712 | Q14: =$N$26*K14/$N$23*1000 -> -0.58058119 | R14: ='Shear flow'!K4 -> 7.6986462 | S14: =(Q14/2)+SQRT(((-Q14/2)^2)+(((R14^2)))) -> 7.4138266 | T14: =(0+Q14/2)-SQRT(((0-Q14/2)^2)+((R14^2))) -> -7.9944078 | U14: =SQRT((S14^2 +T14^2 )-(S14*T14)) -> 13.34708 | V14: =U14*1.5 -> 20.020619
B15: 3 | C15: -800 | D15: 1300 | G15: =$C$27 -> 50 | H15: =C15*G15 -> -40000 | I15: =D15*G15 -> 65000 | J15: =C15-$I$27 -> -800 | K15: =D15-$I$28 -> 599.99218 | N15: =(K15^2)*P15 -> 68678204 | P15: =G15+((E3*F3/6*(2+(K14/K15)))+(E4*F4/6*(2+(K16/K15)))) -> 190.77776 | Q15: =$N$26*K15/$N$23*1000 -> 3.4831692 | R15: ='Shear flow'!K5 -> 5.2538842 | S15: =(Q15/2)+SQRT(((-Q15/2)^2)+(((R15^2)))) -> 7.2766019 | T15: =(0+Q15/2)-SQRT(((0-Q15/2)^2)+((R15^2))) -> -3.7934326 | U15: =SQRT((S15^2 +T15^2 )-(S15*T15)) -> 9.7438373 | V15: =U15*1.5 -> 14.615756
B16: 4 | C16: -550 | D16: 1950 | G16: =$C$27 -> 50 | H16: =C16*G16 -> -27500 | I16: =D16*G16 -> 97500 | J16: =C16-$I$27 -> -550 | K16: =D16-$I$28 -> 1249.9922 | N16: =(K16^2)*P16 -> 2.5831592e+08 | P16: =G16+((E4*F4/6*(2+(K15/K16)))+(E5*F5/6*(2+(K17/K16)))) -> 165.32426 | Q16: =$N$26*K16/$N$23*1000 -> 7.2566518 | R16: ='Shear flow'!K6 -> 0.84014039 | S16: =(Q16/2)+SQRT(((-Q16/2)^2)+(((R16^2)))) -> 7.3526493 | T16: =(0+Q16/2)-SQRT(((0-Q16/2)^2)+((R16^2))) -> -0.095997491 | U16: =SQRT((S16^2 +T16^2 )-(S16*T16)) -> 7.4011149 | V16: =U16*1.5 -> 11.101672
B17: 5 | C17: 0 | D17: 2100 | G17: =$C$28 -> 90 | H17: =C17*G17 -> 0 | I17: =D17*G17 -> 189000 | J17: =C17-$I$27 -> 0 | K17: =D17-$I$28 -> 1399.9922 | N17: =(K17^2)*P17 -> 3.7922296e+08 | P17: =G17+((E5*F5/6*(2+(K16/K17)))+(E6*F6/6*(2+(K18/K17)))) -> 193.48326 | Q17: =$N$26*K17/$N$23*1000 -> 8.1274554 | R17: ='Shear flow'!K7 -> 0 | S17: =(Q17/2)+SQRT(((-Q17/2)^2)+(((R17^2)))) -> 8.1274554 | T17: =(0+Q17/2)-SQRT(((0-Q17/2)^2)+((R17^2))) -> 0 | U17: =SQRT((S17^2 +T17^2 )-(S17*T17)) -> 8.1274554 | V17: =U17*1.5 -> 12.191183
B18: 6 | C18: 550 | D18: 1950 | G18: =$C$27 -> 50 | H18: =C18*G18 -> 27500 | I18: =D18*G18 -> 97500 | J18: =C18-$I$27 -> 550 | K18: =D18-$I$28 -> 1249.9922 | N18: =(K18^2)*P18 -> 2.5831592e+08 | P18: =G18+((E6*F6/6*(2+(K17/K18)))+(E7*F7/6*(2+(K19/K18)))) -> 165.32426 | Q18: =$N$26*K18/$N$23*1000 -> 7.2566518 | R18: ='Shear flow'!K11 -> 0.84014039 | S18: =(Q18/2)+SQRT(((-Q18/2)^2)+(((R18^2)))) -> 7.3526493 | T18: =(0+Q18/2)-SQRT(((0-Q18/2)^2)+((R18^2))) -> -0.095997491 | U18: =SQRT((S18^2 +T18^2 )-(S18*T18)) -> 7.4011149 | V18: =U18*1.5 -> 11.101672
B19: 7 | C19: 800 | D19: 1300 | G19: =$C$27 -> 50 | H19: =C19*G19 -> 40000 | I19: =D19*G19 -> 65000 | J19: =C19-$I$27 -> 800 | K19: =D19-$I$28 -> 599.99218 | N19: =(K19^2)*P19 -> 68678204 | P19: =G19+((E7*F7/6*(2+(K18/K19)))+(E8*F8/6*(2+(K20/K19)))) -> 190.77776 | Q19: =$N$26*K19/$N$23*1000 -> 3.4831692 | R19: ='Shear flow'!K10 -> 5.2538842 | S19: =(Q19/2)+SQRT(((-Q19/2)^2)+(((R19^2)))) -> 7.2766019 | T19: =(0+Q19/2)-SQRT(((0-Q19/2)^2)+((R19^2))) -> -3.7934326 | U19: =SQRT((S19^2 +T19^2 )-(S19*T19)) -> 9.7438373 | V19: =U19*1.5 -> 14.615756
B20: 8 | C20: 800 | D20: 600 | G20: =$C$27 -> 50 | H20: =C20*G20 -> 40000 | I20: =D20*G20 -> 30000 | J20: =C20-$I$27 -> 800 | K20: =D20-$I$28 -> -100.00782 | N20: =(K20^2)*P20 -> 25250662 | P20: =G20+((E8*F8/6*(2+(K19/K20)))+(E9*F9/6*(2+(K21/K20))+(E12*F12/6*(2+L12)))) -> 2524.6712 | Q20: =$N$26*K20/$N$23*1000 -> -0.58058119 | R20: ='Shear flow'!K9 -> 7.6986462 | S20: =(Q20/2)+SQRT(((-Q20/2)^2)+(((R20^2)))) -> 7.4138266 | T20: =(0+Q20/2)-SQRT(((0-Q20/2)^2)+((R20^2))) -> -7.9944078 | U20: =SQRT((S20^2 +T20^2 )-(S20*T20)) -> 13.34708 | V20: =U20*1.5 -> 20.020619
B21: 9 | C21: 700 | D21: 100 | G21: =$C$27 -> 50 | H21: =C21*G21 -> 35000 | I21: =D21*G21 -> 5000 | J21: =C21-$I$27 -> 700 | K21: =D21-$I$28 -> -600.00782 | N21: =(K21^2)*P21 -> 64781750 | P21: =G21+((E9*F9/6*(2+(K20/K21)))+(E10*F10/6*(2+(K22/K21)))) -> 179.94461 | Q21: =$N$26*K21/$N$23*1000 -> -3.4832601 | R21: ='Shear flow'!K8 -> 2.3059985 | S21: =(Q21/2)+SQRT(((-Q21/2)^2)+(((R21^2)))) -> 1.1481631 | T21: =(0+Q21/2)-SQRT(((0-Q21/2)^2)+((R21^2))) -> -4.6314231 | U21: =SQRT((S21^2 +T21^2 )-(S21*T21)) -> 5.2996214 | V21: =U21*1.5 -> 7.9494322
B22: 10 | C22: 0 | D22: 0 | G22: =$C$28 -> 90 | H22: =C22*G22 -> 0 | I22: =D22*G22 -> 0 | J22: =C22-$I$27 -> 0 | K22: =D22-$I$28 -> -700.00782 | N22: =(K22^2)*P22 -> 1.1876936e+08 | P22: =G22+((E10*F10/6*(2+(K21/K22)))+(E11*F11/6*(2+K13/K22))) -> 242.38104 | Q22: =$N$26*K22/$N$23*1000 -> -4.0637958 | R22: =('Shear flow'!K7+'Shear flow'!K2)/2 -> 0 | S22: =(Q22/2)+SQRT(((-Q22/2)^2)+(((R22^2)))) -> 0 | T22: =(0+Q22/2)-SQRT(((0-Q22/2)^2)+((R22^2))) -> -4.0637958 | U22: =SQRT((S22^2 +T22^2 )-(S22*T22)) -> 4.0637958 | V22: =U22*1.5 -> 6.0956937
F23: S | G23: =SUM(G2:G22) -> 6734.632 | H23: =SUM(H2:H22) -> 0 | I23: =SUM(I2:I22) -> 4714295.1 | M23: =SUM(M2:M22) -> 0 | N23: =SUM(N13:N22) -> 1.3320454e+09 | R23: =SUM(R13:R22) -> 32.197338
A25: Upper skin | C25: 0.2
A26: Lower Skin | C26: 0.2 | F26: Location of Centroid | L26: Applied Moment M= | N26: 7733 | P26: Shear force | Q26: 5690
A27: L-Stringer (A) | C27: 50 | F27: S(x*A/Atotal)= Xc = | I27: =$H$23/$G$23 -> 0 | J27: 0 | L27: Material Strength MPa | N27: 470
A28: T-Stringer (A) | C28: 90 | F28: S(y*A/Atotal)=Yc = | I28: =$I$23/$G$23 -> 700.00782 | J28: 1472 | L28: Fatigue limit MPa | N28: 150
A29: U-Stringer (A) | C29: 0

Sheet Data

Sheet Gust Loads
A1: 0 | B1: 1
A2: 21820.39 | B2: 1
A3: 21850.89 | B3: 1.4483192
A4: 21881.39 | B4: 1
A5: 38208.557 | B5: 1
A6: 38239.057 | B6: 0.55168083
A7: 38269.557 | B7: 1
A8: 43671.28 | B8: 1
A9: 43701.78 | B9: 1.4483192
A10: 43732.28 | B10: 1
A11: 65522.169 | B11: 1
A12: 65552.669 | B12: 1.4483192
... A277: 1759027.1 | B277: 1

Sheet Fatigue
A1: Max allowable stress
A2: Load limits
A3: Positive | B3: 3.8 | D3: Max Stress VM (FOS 1.5) | E3: =MAX('Fuselage Stresses'!V13:V22) -> 20.020619 | F3: MPa | W3: Load Factor Max | X3: ='Gust Loads'!B3 -> 1.4483192
A4: Negative | B4: -1.5 | W4: Load Factor Min | X4: ='Gust Loads'!B6 -> 0.55168083
A5: Max Stress | B5: =E3*B3*F10 -> 190.19588 | C5: MPa | D5: Ultimate stress
A6: Min Stress | B6: =E3*B4*F10 -> -75.077323
A7: Amplitude | B7: =(B5-B6)/2 -> 132.6366 | AW7: Initial Crack lenght | AX7: 1 | AY7: mm | BF7: Rainflow Counting Method
A8: Mean stress | B8: =(B5+B6)/2 -> 57.559281 | D8: Ultimate stress | F8: =470 -> 470 | AW8: Plate width (b) | AX8: =20 -> 20 | AY8: mm
A9: Stress Ratio (R) | B9: =B6/B5 -> -0.39473684 | D9: Yield Stress | F9: =325 -> 325 | AW9: a/b | AX9: =AX7/AX8 -> 0.05
A10: Amplitude Ratio (A) | B10: =B7/B8 -> 2.3043478 | D10: K_t Stress concentration factor | F10: 2.5 | AW10: Toughness K_c | AX10: 34
A11: ∆σ | B11: =B5-B6 -> 265.27321 | AR11: hole dimater | AS11: 4 | AW11: A_c (critical crack lenght) | AX11: =(1/PI())*(AX10/(AP25*B5))^2 -> 0.010171986 | AY11: =AX11*1000 -> 10.171986 | AZ11: mm
A12: F | B12: 1 | AR12: b | AS12: 20 | AW12: A/B | AX12: =AX11/(AX8/1000) -> 0.50859928 | AY12: =AY11/AX8 -> 0.50859928
A13: Initial Crack lenght | B13: 1 | C13: mm | D13: Max stress lower than Yield | AR13: d/b | AS13: =AS11/AS12 -> 0.2 | BG13: Notched hole | BO13: Unotched
A14: thick of plate (b) | B14: 50 | C14: mm | G14: n_u = 3.2416 | I14: This is for15m/s but very unfrequent so better to use 3.8 for manouver which is higher | AR14: Stress intensity factor K | AS14: 2.5 | AW14: Keep changing a until u get K=34 and u will get F from that | BG14: A | BI14: B | BO14: A | BQ14: B
A15: a/b | B15: =B13/B14 -> 0.02 | G15: n_d = -1.2416 | BF15: N_i | BG15: =46 -> 46 | BI15: =27 -> 27 | BN15: N_i | BO15: =46 -> 46 | BQ15: =27 -> 27
A16: K_c | B16: 34 | AW16: a | AX16: a/b= alpha | AY16: F | AZ16: K | BF16: Min | BG16: =E3*AS14 -> 50.051548 | BI16: =E3*AS14*'Gust Loads'!B6 -> 27.61248 | BN16: Min | BO16: =E3 -> 20.020619 | BQ16: =E3*'Gust Loads'!B6 -> 11.044992
A17: A_c (critical crack lenght) | B17: =(1/PI()) * (B16/(B12*B5))^2 -> 0.010171986 | C17: =B17*1000 -> 10.171986 | D17: if crack that big = Failure | V17: Unotched | AO17: Notched | AW17: =1/1000 -> 0.001 | AX17: =AW17/($AX$8/1000) -> 0.05 | AY17: =(1- 0.5*AX17 + 0.326*AX17^2)/(SQRT(1-AX17)) -> 1.0011651 | AZ17: =AY17*$B$5*SQRT(PI()*(AW17)) -> 10.672883 | BF17: max | BG17: =E3*AS14*'Gust Loads'!B3 -> 72.490617 | BI17: =E3*AS14 -> 50.051548 | BN17: max | BO17: =E3*'Gust Loads'!B3 -> 28.996247 | BQ17: =E3 -> 20.020619
A18: A/B | B18: =B17/B14 -> 0.00020343971 | V18: Max stress (kt) | W18: =$E$3*$X$3 -> 28.996247 | AO18: Max stress (kt) | AP18: =$E$3*$X$3*$AS$14 -> 72.490617 | AW18: =AW17+0.001 -> 0.002 | AX18: =AW18/($AX$8/1000) -> 0.1 | AY18: =(1- 0.5*AX18 + 0.326*AX18^2)/(SQRT(1-AX18)) -> 1.0048243 | AZ18: =AY18*$B$5*SQRT(PI()*(AW18)) -> 15.148902 | BF18: sigma mean | BG18: =(BG17+BG16)/2 -> 61.271083 | BI18: =(BI17+BI16)/2 -> 38.832014 | BN18: sigma mean | BO18: =(BO17+BO16)/2 -> 24.508433 | BQ18: =(BQ17+BQ16)/2 -> 15.532806
V19: Miin Stress | W19: =E3*X4 -> 11.044992 | AO19: Min Stress | AP19: =E3*X4*AS14 -> 27.61248 | AW19: =AW18+0.001 -> 0.003 | AX19: =AW19/($AX$8/1000) -> 0.15 | AY19: =(1- 0.5*AX19 + 0.326*AX19^2)/(SQRT(1-AX19)) -> 1.0112593 | AZ19: =AY19*$B$5*SQRT(PI()*(AW19)) -> 18.67236 | BF19: sigma_a | BG19: =(BG17-BG16)/2 -> 11.219534 | BI19: =(BI17-BI16)/2 -> 11.219534 | BN19: sigma_a | BO19: =(BO17-BO16)/2 -> 4.4878137 | BQ19: =(BQ17-BQ16)/2 -> 4.4878137
V20: Amplitude | W20: =(W18-W19)/2 -> 8.9756274 | AO20: Amplitude | AP20: =(AP18-AP19)/2 -> 22.439069 | AW20: =AW19+0.001 -> 0.004 | AX20: =AW20/($AX$8/1000) -> 0.2 | AY20: =(1- 0.5*AX20 + 0.326*AX20^2)/(SQRT(1-AX20)) -> 1.0208098 | AZ20: =AY20*$B$5*SQRT(PI()*(AW20)) -> 21.764608 | BF20: sigma_ar | BG20: =BG19/(1-(BG18/AV41)) -> 12.603454 | BI20: =BI19/(1-(BI18/AV41)) -> 12.058718 | BJ20: Morrow | BK20: =(BG20+BI20)/2 -> 12.331086 | BN20: sigma_ar | BO20: =BO19/(1-(BO18/AV41)) -> 4.6939825 | BQ20: =BQ19/(1-(BQ18/AV41)) -> 4.6163161 | BS20: =(BO20+BQ20)/2 -> 4.6551493
D21: σ_fb | E21: 558 | V21: Mean stress | W21: =(W18+W19)/2 -> 20.020619 | AO21: Mean stress | AP21: =(AP18+AP19)/2 -> 50.051548 | AW21: =AW20+0.001 -> 0.005 | AX21: =AW21/($AX$8/1000) -> 0.25 | AY21: =(1- 0.5*AX21 + 0.326*AX21^2)/(SQRT(1-AX21)) -> 1.03389 | AZ21: =AY21*$B$5*SQRT(PI()*(AW21)) -> 24.645372 | BF21: N_f | BG21: =0.5*(BG20/$AV$43)^(1/$AV$42) -> 1.6499352e+16 | BI21: =0.5*(BI20/$AV$43)^(1/$AV$42) -> 2.4393621e+16 | BK21: =(BG21+BI21)/2 -> 2.0446487e+16 | BN21: N_f | BO21: =0.5*(BO20/$AV$43)^(1/$AV$42) -> 1.031497e+20 | BQ21: =0.5*(BQ20/$AV$43)^(1/$AV$42) -> 1.1956145e+20 | BS21: =(BO21+BQ21)/2 -> 1.1135558e+20
D22: b | E22: -0.113 | V22: Stress Ratio (R) | W22: =W19/W18 -> 0.38091109 | AO22: Stress Ratio (R) | AP22: =AP19/AP18 -> 0.38091109 | AW22: =AW21+0.001 -> 0.006 | AX22: =AW22/($AX$8/1000) -> 0.3 | AY22: =(1- 0.5*AX22 + 0.326*AX22^2)/(SQRT(1-AX22)) -> 1.0510123 | AZ22: =AY22*$B$5*SQRT(PI()*(AW22)) -> 27.444763 | BF22: Ni/Nf | BG22: =BG15/BG21 -> 2.7879883e-15 | BI22: =BI15/BI21 -> 1.1068467e-15 | BK22: =BG22+BI22 -> 3.894835e-15 | BN22: Ni/Nf | BO22: =BO15/BO21 -> 4.4595377e-19 | BQ22: =BQ15/BQ21 -> 2.2582529e-19 | BS22: =BO22+BQ22 -> 6.7177907e-19
D23: σ_f | E23: 927 | V23: Amplitude Ratio (A) | W23: =W20/W21 -> 0.44831917 | AO23: Amplitude Ratio (A) | AP23: =AP20/AP21 -> 0.44831917 | AW23: =AW22+0.001 -> 0.007 | AX23: =AW23/($AX$8/1000) -> 0.35 | AY23: =(1- 0.5*AX23 + 0.326*AX23^2)/(SQRT(1-AX23)) -> 1.0728198 | AZ23: =AY23*$B$5*SQRT(PI()*(AW23)) -> 30.258811 | BK23: Proportion of life used
V24: ∆σ | W24: =W18-W19 -> 17.951255 | AO24: ∆σ | AP24: =AP18-AP19 -> 44.878137 | AW24: =AW23+0.001 -> 0.008 | AX24: =AW24/($AX$8/1000) -> 0.4 | AY24: =(1- 0.5*AX24 + 0.326*AX24^2)/(SQRT(1-AX24)) -> 1.1001338 | AZ24: =AY24*$B$5*SQRT(PI()*(AW24)) -> 33.171611 | BF24: B_f | BG24: =1/BK22 -> 2.5675029e+14 | BI24: Number of fights | BN24: B_f | BO24: =1/BS22 -> 1.4885846e+18 | BQ24: How many 1000km u can do
V25: F | W25: 1 | AO25: F | AP25: 1 | AW25: =AW24+0.001 -> 0.009 | AX25: =AW25/($AX$8/1000) -> 0.45 | AY25: =(1- 0.5*AX25 + 0.326*AX25^2)/(SQRT(1-AX25)) -> 1.1340244 | AZ25: =AY25*$B$5*SQRT(PI()*(AW25)) -> 36.267674
A26: N_f | B26: σ_ar | V26: Initial Crack lenght | W26: 0.1 | X26: mm | AW26: =AW25+0.001 -> 0.01 | AX26: =AW26/($AX$8/1000) -> 0.5 | AY26: =(1- 0.5*AX26 + 0.326*AX26^2)/(SQRT(1-AX26)) -> 1.1759186 | AZ26: =AY26*$B$5*SQRT(PI()*(AW26)) -> 39.641794 | BF26: Years | BG26: =BG24/365 -> 7.0342544e+11 | BN26: Years | BO26: =BO24/365 -> 4.0783141e+15
A27: 10 | B27: =$E$23*(2*A27)^$E$22 -> 660.78982 | V27: thick of plate (b) | W27: =20 -> 20 | X27: mm | AW27: =AW26+0.001 -> 0.011 | AX27: =AW27/($AX$8/1000) -> 0.55 | AY27: =(1- 0.5*AX27 + 0.326*AX27^2)/(SQRT(1-AX27)) -> 1.2277728 | AZ27: =AY27*$B$5*SQRT(PI()*(AW27)) -> 43.41006
A28: =A27*10 -> 100 | B28: =$E$23*(2*A28)^$E$22 -> 509.40517 | V28: a/b | W28: =W26/W27 -> 0.005 | AW28: =AW27+0.001 -> 0.012 | AX28: =AW28/($AX$8/1000) -> 0.6 | AY28: =(1- 0.5*AX28 + 0.326*AX28^2)/(SQRT(1-AX28)) -> 1.2923596 | AZ28: =AY28*$B$5*SQRT(PI()*(AW28)) -> 47.725453
A29: =A28*10 -> 1000 | B29: =$E$23*(2*A29)^$E$22 -> 392.70221 | V29: K_c | W29: 34 | AW29: =AW28+0.001 -> 0.013 | AX29: =AW29/($AX$8/1000) -> 0.65 | AY29: =(1- 0.5*AX29 + 0.326*AX29^2)/(SQRT(1-AX29)) -> 1.3737729 | AZ29: =AY29*$B$5*SQRT(PI()*(AW29)) -> 52.803495
A30: =A29*10 -> 10000 | B30: =$E$23*(2*A30)^$E$22 -> 302.7355 | V30: A_c (critical crack lenght) | W30: =(1/PI())*(W29/(W18*W25))^2 -> 0.43764743 | X30: =W30*1000 -> 437.64743 | Y30: mm | AW30: =AW29+0.001 -> 0.014 | AX30: =AW30/($AX$8/1000) -> 0.7 | AY30: =(1- 0.5*AX30 + 0.326*AX30^2)/(SQRT(1-AX30)) -> 1.4783762 | AZ30: =AY30*$B$5*SQRT(PI()*(AW30)) -> 58.969173
A31: =A30*10 -> 100000 | B31: =$E$23*(2*A31)^$E$22 -> 233.37984 | V31: A/B | W31: =X30/W27 -> 21.882372 | X31: mm/mm | AW31: =AW30+0.001 -> 0.015 | AX31: =AW31/($AX$8/1000) -> 0.75 | AY31: =(1- 0.5*AX31 + 0.326*AX31^2)/(SQRT(1-AX31)) -> 1.61675 | AZ31: =AY31*$B$5*SQRT(PI()*(AW31)) -> 66.752041
A32: =A31*10 -> 1000000 | B32: =$E$23*(2*A32)^$E$22 -> 179.91333 | AW32: =AW31+0.001 -> 0.016 | AX32: =AW32/($AX$8/1000) -> 0.8 | AY32: =(1- 0.5*AX32 + 0.326*AX32^2)/(SQRT(1-AX32)) -> 1.808174 | AZ32: =AY32*$B$5*SQRT(PI()*(AW32)) -> 77.103885
A33: =A32*10 -> 10000000 | B33: =$E$23*(2*A33)^$E$22 -> 138.69581 | AW33: =AW32+0.001 -> 0.017 | AX33: =AW33/($AX$8/1000) -> 0.85 | AY33: =(1- 0.5*AX33 + 0.326*AX33^2)/(SQRT(1-AX33)) -> 2.0927924 | AZ33: =AY33*$B$5*SQRT(PI()*(AW33)) -> 91.987042
A34: =A33*10 -> 100000000 | B34: =$E$23*(2*A34)^$E$22 -> 106.92108 | AW34: =AW33+0.001 -> 0.018 | AX34: =AW34/($AX$8/1000) -> 0.9 | AY34: =(1- 0.5*AX34 + 0.326*AX34^2)/(SQRT(1-AX34)) -> 2.5742838 | AZ34: =AY34*$B$5*SQRT(PI()*(AW34)) -> 116.43102
A35: =A34*10 -> 1000000000 | B35: =$E$23*(2*A35)^$E$22 -> 82.425833 | AW35: 0.0035 | AX35: =AW35/($AX$8/1000) -> 0.175 | AY35: =(1- 0.5*AX35 + 0.326*AX35^2)/(SQRT(1-AX35)) -> 1.0156212 | AZ35: =AY35*$B$5*SQRT(PI()*(AW35)) -> 20.255447
A36: =A35*10 -> 10000000000 | B36: =$E$23*(2*A36)^$E$22 -> 63.542361 | AW36: 0.0036 | AX36: =AW36/($AX$8/1000) -> 0.18 | AY36: =(1- 0.5*AX36 + 0.326*AX36^2)/(SQRT(1-AX36)) -> 1.0165911 | AZ36: =AY36*$B$5*SQRT(PI()*(AW36)) -> 20.562391
A37: =A36*10 -> 100000000000 | B37: =$E$23*(2*A37)^$E$22 -> 48.985026 | AC37: σ_fb | AD37: 558 | AW37: 0.0083 | AX37: =AW37/($AX$8/1000) -> 0.415 | AY37: =(1- 0.5*AX37 + 0.326*AX37^2)/(SQRT(1-AX37)) -> 1.1095536 | AZ37: =AY37*$B$5*SQRT(PI()*(AW37)) -> 34.07716
A38: =A37*10 -> 1000000000000 | B38: =$E$23*(2*A38)^$E$22 -> 37.762727 | AC38: b | AD38: -0.113
A39: =A38*10 -> 10000000000000 | B39: =$E$23*(2*A39)^$E$22 -> 29.111417 | AC39: σ_f | AD39: 927
A40: =A39*10 -> 100000000000000 | B40: =$E$23*(2*A40)^$E$22 -> 22.442092
...

Sheet Stress-Strain
A1: Plate Geometry | D1: Load | G1: Mat Props
D2: P | E2: =206.72 -> 206.72 | G2: H' | H2: =662 -> 662
A3: t | B3: 2 | G3: n' | H3: 0.07
A4: b | B4: 20 | G4: E | H4: 73100
A5: Dia | B5: 4 | G5: SigY' | H5: 168
A6: A Reduced | B6: =(B4-B5)*B3 -> 32 | G6: SigF' | H6: 927
A7: S | B7: =Fatigue!E3 -> 20.020619 | G7: EpsF' | H7: 0.409
A8: kt | B8: 2.5 | G8: b | H8: -0.113
G9: c | H9: -0.713 | M9: Intersect | R9: 1st | S9: reverse | T9: difference | W9: 1st | X9: reverse | Y9: difference
M10: 1st | N10: reverse | O10: difference | Q10: 40 | R10: =(Q10/$H$4)+((Q10/$H$2)^(1/$H$3)) -> 0.00054719562 | S10: =(($B$7*$B$8)^2)/(Q10*$H$4) -> 0.00085675701 | T10: =R10-S10 -> -0.00030956139 | V10: 50 | W10: =(V10/$H$4)+((V10/$H$2)^(1/$H$3)) -> 0.00068399453 | X10: =(($B$7*$B$8)^2)/(V10*$H$4) -> 0.00068540561 | Y10: =W10-X10 -> -1.4110791e-06
L11: 0 | M11: =B15 -> 0 | N11: =E15 -> 0.03427028 | O11: =M11-N11 -> -0.03427028 | Q11: 41 | R11: =(Q11/$H$4)+((Q11/$H$2)^(1/$H$3)) -> 0.00056087551 | S11: =(($B$7*$B$8)^2)/(Q11*$H$4) -> 0.0008358605 | T11: =R11-S11 -> -0.00027498498 | V11: =V10+0.1 -> 50.1 | W11: =(V11/$H$4)+((V11/$H$2)^(1/$H$3)) -> 0.00068536252 | X11: =(($B$7*$B$8)^2)/(V11*$H$4) -> 0.00068403753 | Y11: =W11-X11 -> 1.324985e-06
L12: 40 | M12: =B16 -> 0.00027359781 | N12: =E16 -> 0.001713514 | O12: =M12-N12 -> -0.0014399162 | Q12: 42 | R12: =(Q12/$H$4)+((Q12/$H$2)^(1/$H$3)) -> 0.0005745554 | S12: =(($B$7*$B$8)^2)/(Q12*$H$4) -> 0.00081595906 | T12: =R12-S12 -> -0.00024140365 | V12: =V11+0.1 -> 50.2 | W12: =(V12/$H$4)+((V12/$H$2)^(1/$H$3)) -> 0.00068673051 | X12: =(($B$7*$B$8)^2)/(V12*$H$4) -> 0.00068267491 | Y12: =W12-X12 -> 4.0555986e-06
A13: Cyclic Stress Strain curve | D13: Neuber Analysis (first rev) | G13: Neuber Analysis (Second rev) | L13: 45 | M13: =B17 -> 0.00054719562 | N13: =E17 -> 0.00085675701 | O13: =M13-N13 -> -0.00030956139 | Q13: 43 | R13: =(Q13/$H$4)+((Q13/$H$2)^(1/$H$3)) -> 0.00058823529 | S13: =(($B$7*$B$8)^2)/(Q13*$H$4) -> 0.00079698326 | T13: =R13-S13 -> -0.00020874797 | V13: =V12+0.1 -> 50.3 | W13: =(V13/$H$4)+((V13/$H$2)^(1/$H$3)) -> 0.0006880985 | X13: =(($B$7*$B$8)^2)/(V13*$H$4) -> 0.0006813177 | Y13: =W13-X13 -> 6.7807943e-06
A14: Sig | B14: Eps | D14: Sig | E14: Eps | G14: Sig | H14: Eps | L14: 50 | M14: =B18 -> 0.00082079343 | N14: =E18 -> 0.00068403753 | O14: =M14-N14 -> 0.0001367559 | Q14: 44 | R14: =(Q14/$H$4)+((Q14/$H$2)^(1/$H$3)) -> 0.00060191518 | S14: =(($B$7*$B$8)^2)/(Q14*$H$4) -> 0.00077887001 | T14: =R14-S14 -> -0.00017695482 | V14: =V13+0.1 -> 50.4 | W14: =(V14/$H$4)+((V14/$H$2)^(1/$H$3)) -> 0.00068946648 | X14: =(($B$7*$B$8)^2)/(V14*$H$4) -> 0.00067996588 | Y14: =W14-X14 -> 9.5006041e-06
A15: 0 | B15: 0 | D15: 1 | E15: =(($B$7*$B$8)^2)/(D15*$H$4) -> 0.03427028 | G15: 150 | H15: =((2*$B$7*$B$8)^2)/(G15*$H$4) -> 0.00091387414 | L15: 55 | M15: =B19 -> 0.0010943912 | N15: =E19 -> 0.00057117134 | O15: =M15-N15 -> 0.00052321991 | Q15: 45 | R15: =(Q15/$H$4)+((Q15/$H$2)^(1/$H$3)) -> 0.00061559508 | S15: =(($B$7*$B$8)^2)/(Q15*$H$4) -> 0.00076156179 | T15: =R15-S15 -> -0.00014596671 | V15: =V14+0.1 -> 50.5 | W15: =(V15/$H$4)+((V15/$H$2)^(1/$H$3)) -> 0.00069083447 | X15: =(($B$7*$B$8)^2)/(V15*$H$4) -> 0.00067861941 | Y15: =W15-X15 -> 1.221506e-05
A16: 20 | B16: =(A16/$H$4)+((A16/$H$2)^(1/$H$3)) -> 0.00027359781 | D16: 20 | E16: =(($B$7*$B$8)^2)/(D16*$H$4) -> 0.001713514 | G16: 125 | H16: =((2*$B$7*$B$8)^2)/(G16*$H$4) -> 0.001096649 | L16: 60 | M16: =B20 -> 0.0013679891 | N16: =E20 -> 0.0004283785 | O16: =M16-N16 -> 0.00093961055 | Q16: 46 | R16: =(Q16/$H$4)+((Q16/$H$2)^(1/$H$3)) -> 0.00062927497 | S16: =(($B$7*$B$8)^2)/(Q16*$H$4) -> 0.00074500609 | T16: =R16-S16 -> -0.00011573113 | V16: =V15+0.1 -> 50.6 | W16: =(V16/$H$4)+((V16/$H$2)^(1/$H$3)) -> 0.00069220246 | X16: =(($B$7*$B$8)^2)/(V16*$H$4) -> 0.00067727827 | Y16: =W16-X16 -> 1.4924194e-05
A17: 40 | B17: =(A17/$H$4)+((A17/$H$2)^(1/$H$3)) -> 0.00054719562 | D17: 40 | E17: =(($B$7*$B$8)^2)/(D17*$H$4) -> 0.00085675701 | G17: =A31*2 -> 100.2 | H17: =((2*$B$7*$B$8)^2)/(G17*$H$4) -> 0.0013680751 | L17: 65 | M17: =B21 -> 0.0016415869 | N17: =E21 -> 0.0003427028 | O17: =M17-N17 -> 0.0012988841 | Q17: 47 | R17: =(Q17/$H$4)+((Q17/$H$2)^(1/$H$3)) -> 0.00064295486 | S17: =(($B$7*$B$8)^2)/(Q17*$H$4) -> 0.0007291549 | T17: =R17-S17 -> -8.6200045e-05 | V17: =V16+0.1 -> 50.7 | W17: =(V17/$H$4)+((V17/$H$2)^(1/$H$3)) -> 0.00069357045 | X17: =(($B$7*$B$8)^2)/(V17*$H$4) -> 0.00067594241 | Y17: =W17-X17 -> 1.7628038e-05
A18: 60 | B18: =(A18/$H$4)+((A18/$H$2)^(1/$H$3)) -> 0.00082079343 | D18: 50.1 | E18: =(($B$7*$B$8)^2)/(D18*$H$4) -> 0.00068403753 | G18: 75 | H18: =((2*$B$7*$B$8)^2)/(G18*$H$4) -> 0.0018277483 | L18: 70 | M18: =B22 -> 0.0019151849 | N18: =E22 -> 0.00028558567 | O18: =M18-N18 -> 0.0016295992 | Q18: 48 | R18: =(Q18/$H$4)+((Q18/$H$2)^(1/$H$3)) -> 0.00065663475 | S18: =(($B$7*$B$8)^2)/(Q18*$H$4) -> 0.00071396417 | T18: =R18-S18 -> -5.7329427e-05 | V18: =V17+0.1 -> 50.8 | W18: =(V18/$H$4)+((V18/$H$2)^(1/$H$3)) -> 0.00069493844 | X18: =(($B$7*$B$8)^2)/(V18*$H$4) -> 0.00067461182 | Y18: =W18-X18 -> 2.0326622e-05
A19: 80 | B19: =(A19/$H$4)+((A19/$H$2)^(1/$H$3)) -> 0.0010943912 | D19: 60 | E19: =(($B$7*$B$8)^2)/(D19*$H$4) -> 0.00057117134 | G19: 50 | H19: =((2*$B$7*$B$8)^2)/(G19*$H$4) -> 0.0027416224 | L19: 75 | M19: =B23 -> 0.002188784 | N19: =E23 -> 0.00024478772 | O19: =M19-N19 -> 0.0019439963 | Q19: 49 | R19: =(Q19/$H$4)+((Q19/$H$2)^(1/$H$3)) -> 0.00067031464 | S19: =(($B$7*$B$8)^2)/(Q19*$H$4) -> 0.00069939348 | T19: =R19-S19 -> -2.9078839e-05 | V19: =V18+0.1 -> 50.9 | W19: =(V19/$H$4)+((V19/$H$2)^(1/$H$3)) -> 0.00069630643 | X19: =(($B$7*$B$8)^2)/(V19*$H$4) -> 0.00067328645 | Y19: =W19-X19 -> 2.3019979e-05
A20: 100 | B20: =(A20/$H$4)+((A20/$H$2)^(1/$H$3)) -> 0.0013679891 | D20: 80 | E20: =(($B$7*$B$8)^2)/(D20*$H$4) -> 0.0004283785 | G20: 25 | H20: =((2*$B$7*$B$8)^2)/(G20*$H$4) -> 0.0054832449 | L20: 80 | M20: =B24 -> 0.0024623886 | N20: =E24 -> 0.00021418925 | O20: =M20-N20 -> 0.0022481994 | Q20: 50 | R20: =(Q20/$H$4)+((Q20/$H$2)^(1/$H$3)) -> 0.00068399453 | S20: =(($B$7*$B$8)^2)/(Q20*$H$4) -> 0.00068540561 | T20: =R20-S20 -> -1.4110791e-06 | V20: =V19+0.1 -> 51 | W20: =(V20/$H$4)+((V20/$H$2)^(1/$H$3)) -> 0.00069767442 | X20: =(($B$7*$B$8)^2)/(V20*$H$4) -> 0.00067196628 | Y20: =W20-X20 -> 2.5708137e-05
A21: 120 | B21: =(A21/$H$4)+((A21/$H$2)^(1/$H$3)) -> 0.0016415869 | D21: 100 | E21: =(($B$7*$B$8)^2)/(D21*$H$4) -> 0.0003427028 | G21: 50 | H21: =((2*$B$7*$B$8)^2)/(G21*$H$4) -> 0.0027416224 | L21: 85 | M21: =B25 -> 0.0027360156 | N21: =E25 -> 0.00019039045 | O21: =M21-N21 -> 0.0025456252 | Q21: 51 | R21: =(Q21/$H$4)+((Q21/$H$2)^(1/$H$3)) -> 0.00069767442 | S21: =(($B$7*$B$8)^2)/(Q21*$H$4) -> 0.00067196628 | T21: =R21-S21 -> 2.5708137e-05 | V21: =V20+0.1 -> 51.1 | W21: =(V21/$H$4)+((V21/$H$2)^(1/$H$3)) -> 0.00069904241 | X21: =(($B$7*$B$8)^2)/(V21*$H$4) -> 0.00067065128 | Y21: =W21-X21 -> 2.8391129e-05
A22: 140 | B22: =(A22/$H$4)+((A22/$H$2)^(1/$H$3)) -> 0.0019151849 | D22: 120 | E22: =(($B$7*$B$8)^2)/(D22*$H$4) -> 0.00028558567 | G22: 25 | H22: =((2*$B$7*$B$8)^2)/(G22*$H$4) -> 0.0054832449 | L22: 90 | M22: =B26 -> 0.0030097222 | N22: =E26 -> 0.0001713514 | O22: =M22-N22 -> 0.0028383708 | Q22: 52 | R22: =(Q22/$H$4)+((Q22/$H$2)^(1/$H$3)) -> 0.00071135431 | S22: =(($B$7*$B$8)^2)/(Q22*$H$4) -> 0.00065904385 | T22: =R22-S22 -> 5.2310456e-05 | V22: =V21+0.1 -> 51.2 | W22: =(V22/$H$4)+((V22/$H$2)^(1/$H$3)) -> 0.0007004104 | X22: =(($B$7*$B$8)^2)/(V22*$H$4) -> 0.00066934141 | Y22: =W22-X22 -> 3.1068983e-05
A23: 160 | B23: =(A23/$H$4)+((A23/$H$2)^(1/$H$3)) -> 0.002188784 | D23: 140 | E23: =(($B$7*$B$8)^2)/(D23*$H$4) -> 0.00024478772 | H23: Re-Align to lower loop | L23: 95 | M23: =B27 -> 0.0032836808 | N23: =E27 -> 0.000155774 | O23: =M23-N23 -> 0.0031279068 | Q23: 53 | R23: =(Q23/$H$4)+((Q23/$H$2)^(1/$H$3)) -> 0.0007250342 | S23: =(($B$7*$B$8)^2)/(Q23*$H$4) -> 0.00064660906 | T23: =R23-S23 -> 7.8425136e-05 | V23: =V22+0.1 -> 51.3 | W23: =(V23/$H$4)+((V23/$H$2)^(1/$H$3)) -> 0.00070177839 | X23: =(($B$7*$B$8)^2)/(V23*$H$4) -> 0.00066803665 | Y23: =W23-X23 -> 3.3741732e-05
A24: 180 | B24: =(A24/$H$4)+((A24/$H$2)^(1/$H$3)) -> 0.0024623886 | D24: 160 | E24: =(($B$7*$B$8)^2)/(D24*$H$4) -> 0.00021418925 | H24: =$A$31-G15 -> -99.9 | I24: =$C$31-H15 -> -0.00022851163 | L24: 100 | M24: =B28 -> 0.0035583625 | N24: =E28 -> 0.00014279283 | O24: =M24-N24 -> 0.0034155696 | Q24: 54 | R24: =(Q24/$H$4)+((Q24/$H$2)^(1/$H$3)) -> 0.00073871409 | S24: =(($B$7*$B$8)^2)/(Q24*$H$4) -> 0.00063463482 | T24: =R24-S24 -> 0.00010407927 | V24: =V23+0.1 -> 51.4 | W24: =(V24/$H$4)+((V24/$H$2)^(1/$H$3)) -> 0.00070314637 | X24: =(($B$7*$B$8)^2)/(V24*$H$4) -> 0.00066673697 | Y24: =W24-X24 -> 3.6409403e-05
A25: 200 | B25: =(A25/$H$4)+((A25/$H$2)^(1/$H$3)) -> 0.0027360156 | D25: 180 | E25: =(($B$7*$B$8)^2)/(D25*$H$4) -> 0.00019039045 | H25: =$A$31-G16 -> -74.9 | I25: =$C$31-H16 -> -0.00041128645 | V25: =V24+0.1 -> 51.5 | W25: =(V25/$H$4)+((V25/$H$2)^(1/$H$3)) -> 0.00070451436 | X25: =(($B$7*$B$8)^2)/(V25*$H$4) -> 0.00066544234 | Y25: =W25-X25 -> 3.9072027e-05
A26: 220 | B26: =(A26/$H$4)+((A26/$H$2)^(1/$H$3)) -> 0.0030097222 | D26: 200 | E26: =(($B$7*$B$8)^2)/(D26*$H$4) -> 0.0001713514 | H26: =$A$31-G17 -> -50.1 | I26: =$C$31-H17 -> -0.00068271255 | V26: =V25+0.1 -> 51.6 | W26: =(V26/$H$4)+((V26/$H$2)^(1/$H$3)) -> 0.00070588235 | X26: =(($B$7*$B$8)^2)/(V26*$H$4) -> 0.00066415272 | Y26: =W26-X26 -> 4.1729633e-05
A27: 240 | B27: =(A27/$H$4)+((A27/$H$2)^(1/$H$3)) -> 0.0032836808 | D27: 220 | E27: =(($B$7*$B$8)^2)/(D27*$H$4) -> 0.000155774 | H27: =$A$31-G18 -> -24.9 | I27: =$C$31-H18 -> -0.0011423858 | V27: =V26+0.1 -> 51.7 | W27: =(V27/$H$4)+((V27/$H$2)^(1/$H$3)) -> 0.00070725034 | X27: =(($B$7*$B$8)^2)/(V27*$H$4) -> 0.00066286809 | Y27: =W27-X27 -> 4.438225e-05
A28: 260 | B28: =(A28/$H$4)+((A28/$H$2)^(1/$H$3)) -> 0.0035583625 | D28: 240 | E28: =(($B$7*$B$8)^2)/(D28*$H$4) -> 0.00014279283 | H28: =$A$31-G19 -> 0.1 | I28: =$C$31-H19 -> -0.0020562599 | V28: =V27+0.1 -> 51.8 | W28: =(V28/$H$4)+((V28/$H$2)^(1/$H$3)) -> 0.00070861833 | X28: =(($B$7*$B$8)^2)/(V28*$H$4) -> 0.00066158842 | Y28: =W28-X28 -> 4.7029907e-05
H29: =$A$31-G20 -> 25.1 | I29: =$C$31-H20 -> -0.0047978823 | V29: =V28+0.1 -> 51.9 | W29: =(V29/$H$4)+((V29/$H$2)^(1/$H$3)) -> 0.00070998632 | X29: =(($B$7*$B$8)^2)/(V29*$H$4) -> 0.00066031369 | Y29: =W29-X29 -> 4.9672633e-05
A30: Sig | C30: EpsR-O | D30: EpsN | F30: EpsAmp | H30: =$A$31-G21 -> 0.1 | I30: =$C$31-H21 -> -0.0020562599 | V30: =V29+0.1 -> 52 | W30: =(V30/$H$4)+((V30/$H$2)^(1/$H$3)) -> 0.00071135431 | X30: =(($B$7*$B$8)^2)/(V30*$H$4) -> 0.00065904385 | Y30: =W30-X30 -> 5.2310456e-05
A31: 50.1 | C31: =(A31/$H$4)+((A31/$H$2)^(1/$H$3)) -> 0.00068536252 | D31: =(($B$7*$B$8)^2)/(A31*$H$4) -> 0.00068403753 | F31: =D31 -> 0.00068403753 | V31: =V30+0.1 -> 52.1 | W31: =(V31/$H$4)+((V31/$H$2)^(1/$H$3)) -> 0.0007127223 | X31: =(($B$7*$B$8)^2)/(V31*$H$4) -> 0.00065777889 | Y31: =W31-X31 -> 5.4943405e-05
A32: 50.1 | B32: =A32*2 -> 100.2 | C32: =C31-(((A32/H4)+((A32/H2)^(1/H3)))*2) -> -0.00068536252 | D32: =D31-(((2*$B$7*$B$8)^2)/(B32*$H$4)) -> -0.00068403753 | V32: =V31+0.1 -> 52.2 | W32: =(V32/$H$4)+((V32/$H$2)^(1/$H$3)) -> 0.00071409029 | X32: =(($B$7*$B$8)^2)/(V32*$H$4) -> 0.00065651878 | Y32: =W32-X32 -> 5.7571506e-05
V33: =V32+0.1 -> 52.3 | W33: =(V33/$H$4)+((V33/$H$2)^(1/$H$3)) -> 0.00071545828 | X33: =(($B$7*$B$8)^2)/(V33*$H$4) -> 0.00065526349 | Y33: =W33-X33 -> 6.019479e-05
A34: Hyeteresis Loop | V34: =V33+0.1 -> 52.4 | W34: =(V34/$H$4)+((V34/$H$2)^(1/$H$3)) -> 0.00071682627 | X34: =(($B$7*$B$8)^2)/(V34*$H$4) -> 0.00065401298 | Y34: =W34-X34 -> 6.2813281e-05
A35: Sig | B35: Eps | V35: =V34+0.1 -> 52.5 | W35: =(V35/$H$4)+((V35/$H$2)^(1/$H$3)) -> 0.00071819425 | X35: =(($B$7*$B$8)^2)/(V35*$H$4) -> 0.00065276724 | Y35: =W35-X35 -> 6.542701e-05
A36: =$A$31-(A15*2) -> 50.1 | B36: =$C$31-(B15*2) -> 0.00068536252 | V36: =V35+0.1 -> 52.6 | W36: =(V36/$H$4)+((V36/$H$2)^(1/$H$3)) -> 0.00071956224 | X36: =(($B$7*$B$8)^2)/(V36*$H$4) -> 0.00065152624 | Y36: =W36-X36 -> 6.8036001e-05
A37: =$A$31-(A16*2) -> 10.1 | B37: =$C$31-(B16*2) -> 0.00013816689 | V37: =V36+0.1 -> 52.7 | W37: =(V37/$H$4)+((V37/$H$2)^(1/$H$3)) -> 0.00072093023 | X37: =(($B$7*$B$8)^2)/(V37*$H$4) -> 0.00065028995 | Y37: =W37-X37 -> 7.0640283e-05
A38: =$A$31-(A17*2) -> -29.9 | B38: =$C$31-(B17*2) -> -0.00040902873 | V38: =V37+0.1 -> 52.8 | W38: =(V38/$H$4)+((V38/$H$2)^(1/$H$3)) -> 0.00072229822 | X38: =(($B$7*$B$8)^2)/(V38*$H$4) -> 0.00064905834 | Y38: =W38-X38 -> 7.3239881e-05
A39: =$A$31-(A18*2) -> -69.9 | B39: =$C$31-(B18*2) -> -0.00095622435
A40: =$A$31-(A19*2) -> -109.9 | B40: =$C$31-(B19*2) -> -0.00150342
...

Sheet New paris law
A1: C_0 | B1: =(1.42*10^-8)/1000 -> 1.42e-11 | D1: Crack length | E1: Delta K | F1: a/b | G1: F | H1: da/dN | I1: Numb of Cycles for incremment | J1: cumulative
A2: C | B2: =B1/((1-$B$8)^($B$3*(1-$B$5))) -> 2.4633293e-11 | D2: 0.0001 | E2: =$B$9*$B$4*(SQRT(PI()*D2)) -> 0.88258809 | F2: =D2/$B$7 -> 0.005 | G2: =(1- 0.5*F2 + 0.326*F2^2)/(SQRT(1-F2)) -> 1.0000113 | H2: =$B$1*(E2^$B$3) -> 9.069008e-12 | I2: =(0.1/1000)/H2 -> 11026564 | J2: =I2 -> 11026564
A3: m | B3: 3.59 | D3: =D2+0.0001 -> 0.0002 | E3: =$B$9*$B$4*(SQRT(PI()*D3)) -> 1.248168 | F3: =D3/$B$7 -> 0.01 | G3: =(1- 0.5*F3 + 0.326*F3^2)/(SQRT(1-F3)) -> 1.0000454 | H3: =$B$1*(E3^$B$3) -> 3.1470861e-11 | I3: =(0.1/1000)/H3 -> 3177542.5 | J3: =J2+I3 -> 14204107
A4: Delta sigma | B4: =Fatigue!$AP$24 -> 44.878137 | D4: =D3+0.0001 -> 0.0003 | E4: =$B$9*$B$4*(SQRT(PI()*D4)) -> 1.5286874 | F4: =D4/$B$7 -> 0.015 | G4: =(1- 0.5*F4 + 0.326*F4^2)/(SQRT(1-F4)) -> 1.0001025 | H4: =$B$1*(E4^$B$3) -> 6.5161704e-11 | I4: =(0.1/1000)/H4 -> 1534643.7 | J4: =J3+I4 -> 15738751
A5: gamma | B5: 0.68 | D5: =D4+0.0001 -> 0.0004 | E5: =$B$9*$B$4*(SQRT(PI()*D5)) -> 1.7651762 | F5: =D5/$B$7 -> 0.02 | G5: =(1- 0.5*F5 + 0.326*F5^2)/(SQRT(1-F5)) -> 1.0001827 | H5: =$B$1*(E5^$B$3) -> 1.0920876e-10 | I5: =(0.1/1000)/H5 -> 915677.48 | J5: =J4+I5 -> 16654428
A6: delta a | B6: =0.1/1000 -> 0.0001 | C6: m | D6: =D5+0.0001 -> 0.0005 | E6: =$B$9*$B$4*(SQRT(PI()*D6)) -> 1.973527 | F6: =D6/$B$7 -> 0.025 | G6: =(1- 0.5*F6 + 0.326*F6^2)/(SQRT(1-F6)) -> 1.0002865 | H6: =$B$1*(E6^$B$3) -> 1.6300876e-10 | I6: =(0.1/1000)/H6 -> 613463.97 | J6: =J5+I6 -> 17267892
A7: b | B7: =20/1000 -> 0.02 | D7: =D6+0.0001 -> 0.0006 | E7: =$B$9*$B$4*(SQRT(PI()*D7)) -> 2.1618905 | F7: =D7/$B$7 -> 0.03 | G7: =(1- 0.5*F7 + 0.326*F7^2)/(SQRT(1-F7)) -> 1.0004139 | H7: =$B$1*(E7^$B$3) -> 2.261212e-10 | I7: =(0.1/1000)/H7 -> 442240.71 | J7: =J6+I7 -> 17710133
A8: R | B8: =Fatigue!$AP$22 -> 0.38091109 | D8: =D7+0.0001 -> 0.0007 | E8: =$B$9*$B$4*(SQRT(PI()*D8)) -> 2.3351086 | F8: =D8/$B$7 -> 0.035 | G8: =(1- 0.5*F8 + 0.326*F8^2)/(SQRT(1-F8)) -> 1.0005652 | H8: =$B$1*(E8^$B$3) -> 2.9820215e-10 | I8: =(0.1/1000)/H8 -> 335342.99 | J8: =J7+I8 -> 18045476
A9: F | B9: =Fatigue!AY37 -> 1.1095536 | D9: =D8+0.0001 -> 0.0008 | E9: =$B$9*$B$4*(SQRT(PI()*D9)) -> 2.4963361 | F9: =D9/$B$7 -> 0.04 | G9: =(1- 0.5*F9 + 0.326*F9^2)/(SQRT(1-F9)) -> 1.0007407 | H9: =$B$1*(E9^$B$3) -> 3.7897129e-10 | I9: =(0.1/1000)/H9 -> 263872.23 | J9: =J8+I9 -> 18309348
D10: =D9+0.0001 -> 0.0009 | E10: =$B$9*$B$4*(SQRT(PI()*D10)) -> 2.6477643 | F10: =D10/$B$7 -> 0.045 | G10: =(1- 0.5*F10 + 0.326*F10^2)/(SQRT(1-F10)) -> 1.0009405 | H10: =$B$1*(E10^$B$3) -> 4.6819319e-10 | I10: =(0.1/1000)/H10 -> 213587.05 | J10: =J9+I10 -> 18522935
A11: a_c | B11: =Fatigue!AW37 -> 0.0083 | D11: =D10+0.0001 -> 0.001 | E11: =$B$9*$B$4*(SQRT(PI()*D11)) -> 2.7909886 | F11: =D11/$B$7 -> 0.05 | G11: =(1- 0.5*F11 + 0.326*F11^2)/(SQRT(1-F11)) -> 1.0011651 | H11: =$B$1*(E11^$B$3) -> 5.6566562e-10 | I11: =(0.1/1000)/H11 -> 176782.88 | J11: =J10+I11 -> 18699718
A12: N_f | B12: =$I$84+$J$83 -> 20426189 | D12: =D11+0.0001 -> 0.0011 | E12: =$B$9*$B$4*(SQRT(PI()*D12)) -> 2.9272135 | F12: =D12/$B$7 -> 0.055 | G12: =(1- 0.5*F12 + 0.326*F12^2)/(SQRT(1-F12)) -> 1.0014145 | H12: =$B$1*(E12^$B$3) -> 6.7121191e-10 | I12: =(0.1/1000)/H12 -> 148984.25 | J12: =J11+I12 -> 18848702
D13: =D12+0.0001 -> 0.0012 | E13: =$B$9*$B$4*(SQRT(PI()*D13)) -> 3.0573748 | F13: =D13/$B$7 -> 0.06 | G13: =(1- 0.5*F13 + 0.326*F13^2)/(SQRT(1-F13)) -> 1.0016891 | H13: =$B$1*(E13^$B$3) -> 7.8467555e-10 | I13: =(0.1/1000)/H13 -> 127441.21 | J13: =J12+I13 -> 18976143
A14: 1 cycle | B14: =1.53*10^5/1000 -> 153 | C14: km | D14: =D13+0.0001 -> 0.0013 | E14: =$B$9*$B$4*(SQRT(PI()*D14)) -> 3.1822166 | F14: =D14/$B$7 -> 0.065 | G14: =(1- 0.5*F14 + 0.326*F14^2)/(SQRT(1-F14)) -> 1.0019891 | H14: =$B$1*(E14^$B$3) -> 9.0591636e-10 | I14: =(0.1/1000)/H14 -> 110385.47 | J14: =J13+I14 -> 19086529
A15: 1 trip | B15: 1000 | D15: =D14+0.0001 -> 0.0014 | E15: =$B$9*$B$4*(SQRT(PI()*D15)) -> 3.3023422 | F15: =D15/$B$7 -> 0.07 | G15: =(1- 0.5*F15 + 0.326*F15^2)/(SQRT(1-F15)) -> 1.0023148 | H15: =$B$1*(E15^$B$3) -> 1.0348076e-09 | I15: =(0.1/1000)/H15 -> 96636.322 | J15: =J14+I15 -> 19183165
A16: cycles per trip | B16: =36 -> 36 | D16: =D15+0.0001 -> 0.0015 | E16: =$B$9*$B$4*(SQRT(PI()*D16)) -> 3.418249 | F16: =D16/$B$7 -> 0.075 | G16: =(1- 0.5*F16 + 0.326*F16^2)/(SQRT(1-F16)) -> 1.0026665 | H16: =$B$1*(E16^$B$3) -> 1.1712338e-09 | I16: =(0.1/1000)/H16 -> 85380.05 | J16: =J15+I16 -> 19268545
A17: trips | B17: =B12/B16 -> 567394.15 | D17: =D16+0.0001 -> 0.0016 | E17: =$B$9*$B$4*(SQRT(PI()*D17)) -> 3.5303523 | F17: =D17/$B$7 -> 0.08 | G17: =(1- 0.5*F17 + 0.326*F17^2)/(SQRT(1-F17)) -> 1.0030444 | H17: =$B$1*(E17^$B$3) -> 1.315089e-09 | I17: =(0.1/1000)/H17 -> 76040.48 | J17: =J16+I17 -> 19344586
A18: 1 trip per day | B18: =B17/365 -> 1554.5045 | C18: Years | D18: =D17+0.0001 -> 0.0017 | E18: =$B$9*$B$4*(SQRT(PI()*D18)) -> 3.6390039 | F18: =D18/$B$7 -> 0.085 | G18: =(1- 0.5*F18 + 0.326*F18^2)/(SQRT(1-F18)) -> 1.0034489 | H18: =$B$1*(E18^$B$3) -> 1.4662756e-09 | I18: =(0.1/1000)/H18 -> 68200.004 | J18: =J17+I18 -> 19412786
D19: =D18+0.0001 -> 0.0018 | E19: =$B$9*$B$4*(SQRT(PI()*D19)) -> 3.7445041 | F19: =D19/$B$7 -> 0.09 | G19: =(1- 0.5*F19 + 0.326*F19^2)/(SQRT(1-F19)) -> 1.0038801 | H19: =$B$1*(E19^$B$3) -> 1.6247028e-09 | I19: =(0.1/1000)/H19 -> 61549.718 | J19: =J18+I19 -> 19474335
D20: =D19+0.0001 -> 0.0019 | E20: =$B$9*$B$4*(SQRT(PI()*D20)) -> 3.8471123 | F20: =D20/$B$7 -> 0.095 | G20: =(1- 0.5*F20 + 0.326*F20^2)/(SQRT(1-F20)) -> 1.0043385 | H20: =$B$1*(E20^$B$3) -> 1.7902863e-09 | I20: =(0.1/1000)/H20 -> 55856.987 | J20: =J19+I20 -> 19530192
D21: =D20+0.0001 -> 0.002 | E21: =$B$9*$B$4*(SQRT(PI()*D21)) -> 3.9470539 | F21: =D21/$B$7 -> 0.1 | G21: =(1- 0.5*F21 + 0.326*F21^2)/(SQRT(1-F21)) -> 1.0048243 | H21: =$B$1*(E21^$B$3) -> 1.9629472e-09 | I21: =(0.1/1000)/H21 -> 50943.804 | J21: =J20+I21 -> 19581136
D22: =D21+0.0001 -> 0.0021 | E22: =$B$9*$B$4*(SQRT(PI()*D22)) -> 4.0445267 | F22: =D22/$B$7 -> 0.105 | G22: =(1- 0.5*F22 + 0.326*F22^2)/(SQRT(1-F22)) -> 1.0053378 | H22: =$B$1*(E22^$B$3) -> 2.1426114e-09 | I22: =(0.1/1000)/H22 -> 46672.018 | J22: =J21+I22 -> 19627808
D23: =D22+0.0001 -> 0.0022 | E23: =$B$9*$B$4*(SQRT(PI()*D23)) -> 4.1397051 | F23: =D23/$B$7 -> 0.11 | G23: =(1- 0.5*F23 + 0.326*F23^2)/(SQRT(1-F23)) -> 1.0058793 | H23: =$B$1*(E23^$B$3) -> 2.3292092e-09 | I23: =(0.1/1000)/H23 -> 42933.026 | J23: =J22+I23 -> 19670741
D24: =D23+0.0001 -> 0.0023 | E24: =$B$9*$B$4*(SQRT(PI()*D24)) -> 4.2327438 | F24: =D24/$B$7 -> 0.115 | G24: =(1- 0.5*F24 + 0.326*F24^2)/(SQRT(1-F24)) -> 1.0064491 | H24: =$B$1*(E24^$B$3) -> 2.5226747e-09 | I24: =(0.1/1000)/H24 -> 39640.466 | J24: =J23+I24 -> 19710382
D25: =D24+0.0001 -> 0.0024 | E25: =$B$9*$B$4*(SQRT(PI()*D25)) -> 4.3237809 | F25: =D25/$B$7 -> 0.12 | G25: =(1- 0.5*F25 + 0.326*F25^2)/(SQRT(1-F25)) -> 1.0070476 | H25: =$B$1*(E25^$B$3) -> 2.7229456e-09 | I25: =(0.1/1000)/H25 -> 36724.935 | J25: =J24+I25 -> 19747107
D26: =D25+0.0001 -> 0.0025 | E26: =$B$9*$B$4*(SQRT(PI()*D26)) -> 4.4129404 | F26: =D26/$B$7 -> 0.125 | G26: =(1- 0.5*F26 + 0.326*F26^2)/(SQRT(1-F26)) -> 1.0076751 | H26: =$B$1*(E26^$B$3) -> 2.9299628e-09 | I26: =(0.1/1000)/H26 -> 34130.127 | J26: =J25+I26 -> 19781237
D27: =D26+0.0001 -> 0.0026 | E27: =$B$9*$B$4*(SQRT(PI()*D27)) -> 4.5003339 | F27: =D27/$B$7 -> 0.13 | G27: =(1- 0.5*F27 + 0.326*F27^2)/(SQRT(1-F27)) -> 1.0083319 | H27: =$B$1*(E27^$B$3) -> 3.1436699e-09 | I27: =(0.1/1000)/H27 -> 31809.955 | J27: =J26+I27 -> 19813047
D28: =D27+0.0001 -> 0.0027 | E28: =$B$9*$B$4*(SQRT(PI()*D28)) -> 4.5860622 | F28: =D28/$B$7 -> 0.135 | G28: =(1- 0.5*F28 + 0.326*F28^2)/(SQRT(1-F28)) -> 1.0090184 | H28: =$B$1*(E28^$B$3) -> 3.3640136e-09 | I28: =(0.1/1000)/H28 -> 29726.396 | J28: =J27+I28 -> 19842773
D29: =D28+0.0001 -> 0.0028 | E29: =$B$9*$B$4*(SQRT(PI()*D29)) -> 4.6702172 | F29: =D29/$B$7 -> 0.14 | G29: =(1- 0.5*F29 + 0.326*F29^2)/(SQRT(1-F29)) -> 1.0097349 | H29: =$B$1*(E29^$B$3) -> 3.5909425e-09 | I29: =(0.1/1000)/H29 -> 27847.842 | J29: =J28+I29 -> 19870621
D30: =D29+0.0001 -> 0.0029 | E30: =$B$9*$B$4*(SQRT(PI()*D30)) -> 4.7528823 | F30: =D30/$B$7 -> 0.145 | G30: =(1- 0.5*F30 + 0.326*F30^2)/(SQRT(1-F30)) -> 1.0104817 | H30: =$B$1*(E30^$B$3) -> 3.8244078e-09 | I30: =(0.1/1000)/H30 -> 26147.839 | J30: =J29+I30 -> 19896769
... D200: =D199+0.0001 -> 0.0199 | E200: =$B$9*$B$4*(SQRT(PI()*D200)) -> 12.450437 | F200: =D200/$B$7 -> 0.995 | G200: =(1- 0.5*F200 + 0.326*F200^2)/(SQRT(1-F200)) -> 11.670771 | H200: =$B$1*(E200^$B$3) -> 1.2133918e-07 | I200: =(0.1/1000)/H200 -> 824.13611 | J200: =J199+I200 -> 20631769
